Workbook

Sheet 시도별 현황
A1: 2026 전국 AI 중점학교 · AI·디지털 활용 선도학교 — 시도별 공개·확보 현황
A2: 확보 수는 명단 탭을 COUNTIFS로 집계(명단 수정 시 자동 반영). 교육부 지정 수는 2026 AI 중점학교 교육부 발표 시도별 수치. 미공개 시도는 붉은 칸.
A4: ① 시도별 현황표
A5: 시도 | B5: AI 교육부 지정 | C5: AI 확보 | D5: 확보율 | E5: AI 명단 | F5: 디지털 발표 수 | G5: 디지털 확보 | H5: 디지털 명단 | I5: 합계(확보) | J5: 비고
A6: 서울 | B6: 182 | C6: =COUNTIFS('AI 중점학교'!$B$5:$B$989,"서울") -> 182 | D6: =IFERROR(C6/B6,0) -> 1 | E6: 공개 | F6: - | G6: =COUNTIFS('AI·디지털 선도학교'!$B$5:$B$1058,"서울") -> 190 | H6: 공개 | I6: =C6+G6 -> 372
A7: 부산 | B7: 44 | C7: =COUNTIFS('AI 중점학교'!$B$5:$B$989,"부산") -> 44 | D7: =IFERROR(C7/B7,0) -> 1 | E7: 공개 | F7: - | G7: =COUNTIFS('AI·디지털 선도학교'!$B$5:$B$1058,"부산") -> 78 | H7: 공개 | I7: =C7+G7 -> 122
A8: 대구 | B8: 60 | C8: =COUNTIFS('AI 중점학교'!$B$5:$B$989,"대구") -> 60 | D8: =IFERROR(C8/B8,0) -> 1 | E8: 공개 | F8: - | G8: =COUNTIFS('AI·디지털 선도학교'!$B$5:$B$1058,"대구") -> 125 | H8: 공개 | I8: =C8+G8 -> 185 | J8: AI 유형1·2·3(대구 자체 분류)
A9: 인천 | B9: 107 | C9: =COUNTIFS('AI 중점학교'!$B$5:$B$989,"인천") -> 107 | D9: =IFERROR(C9/B9,0) -> 1 | E9: 공개 | F9: - | G9: =COUNTIFS('AI·디지털 선도학교'!$B$5:$B$1058,"인천") -> 73 | H9: 공개 | I9: =C9+G9 -> 180 | J9: 디지털: 연구학교 3교 포함
A10: 광주 | B10: 27 | C10: =COUNTIFS('AI 중점학교'!$B$5:$B$989,"광주") -> 27 | D10: =IFERROR(C10/B10,0) -> 1 | E10: 공개 | F10: - | G10: =COUNTIFS('AI·디지털 선도학교'!$B$5:$B$1058,"광주") -> 40 | H10: 공개 | I10: =C10+G10 -> 67 | J10: 2026 전남광주 통합 – 나이스 주소·관할청 표기 기준
A11: 대전 | B11: 24 | C11: =COUNTIFS('AI 중점학교'!$B$5:$B$989,"대전") -> 22 | D11: =IFERROR(C11/B11,0) -> 0.91666667 | E11: 공개 | F11: - | G11: =COUNTIFS('AI·디지털 선도학교'!$B$5:$B$1058,"대전") -> 35 | H11: 공개 | I11: =C11+G11 -> 57 | J11: AI: 교육부 24교 중 22교 확인 / 디지털: 연구학교 3교 포함
A12: 울산 | B12: 16 | C12: =COUNTIFS('AI 중점학교'!$B$5:$B$989,"울산") -> 16 | D12: =IFERROR(C12/B12,0) -> 1 | E12: 공개 | F12: - | G12: =COUNTIFS('AI·디지털 선도학교'!$B$5:$B$1058,"울산") -> 28 | H12: 공개 | I12: =C12+G12 -> 44
A13: 세종 | B13: 42 | C13: =COUNTIFS('AI 중점학교'!$B$5:$B$989,"세종") -> 0 | D13: =IFERROR(C13/B13,0) -> 0 | E13: 미공개 | F13: - | G13: =COUNTIFS('AI·디지털 선도학교'!$B$5:$B$1058,"세종") -> 0 | H13: 미공개 | I13: =C13+G13 -> 0 | J13: AI·디지털 명단 비공개
A14: 경기 | B14: 200 | C14: =COUNTIFS('AI 중점학교'!$B$5:$B$989,"경기") -> 200 | D14: =IFERROR(C14/B14,0) -> 1 | E14: 공개 | F14: 350 | G14: =COUNTIFS('AI·디지털 선도학교'!$B$5:$B$1058,"경기") -> 0 | H14: 미공개 | I14: =C14+G14 -> 200 | J14: AI 1교 운영유형 확인필요 / 디지털 350교 선정 발표됐으나 명단 비공개
A15: 강원 | B15: 26 | C15: =COUNTIFS('AI 중점학교'!$B$5:$B$989,"강원") -> 0 | D15: =IFERROR(C15/B15,0) -> 0 | E15: 미공개 | F15: - | G15: =COUNTIFS('AI·디지털 선도학교'!$B$5:$B$1058,"강원") -> 0 | H15: 미공개 | I15: =C15+G15 -> 0 | J15: AI·디지털 명단 비공개
A16: 충북 | B16: 40 | C16: =COUNTIFS('AI 중점학교'!$B$5:$B$989,"충북") -> 40 | D16: =IFERROR(C16/B16,0) -> 1 | E16: 공개 | F16: - | G16: =COUNTIFS('AI·디지털 선도학교'!$B$5:$B$1058,"충북") -> 150 | H16: 공개 | I16: =C16+G16 -> 190
A17: 충남 | B17: 113 | C17: =COUNTIFS('AI 중점학교'!$B$5:$B$989,"충남") -> 0 | D17: =IFERROR(C17/B17,0) -> 0 | E17: 미공개 | F17: - | G17: =COUNTIFS('AI·디지털 선도학교'!$B$5:$B$1058,"충남") -> 0 | H17: 미공개 | I17: =C17+G17 -> 0 | J17: AI·디지털 명단 비공개
A18: 전북 | B18: 81 | C18: =COUNTIFS('AI 중점학교'!$B$5:$B$989,"전북") -> 81 | D18: =IFERROR(C18/B18,0) -> 1 | E18: 공개 | F18: - | G18: =COUNTIFS('AI·디지털 선도학교'!$B$5:$B$1058,"전북") -> 100 | H18: 공개 | I18: =C18+G18 -> 181
A19: 전남 | B19: 34 | C19: =COUNTIFS('AI 중점학교'!$B$5:$B$989,"전남") -> 62 | D19: =IFERROR(C19/B19,0) -> 1.8235294 | E19: 공개 | F19: - | G19: =COUNTIFS('AI·디지털 선도학교'!$B$5:$B$1058,"전남") -> 85 | H19: 공개 | I19: =C19+G19 -> 147 | J19: AI: 교육청 공개 62교(교육부 집계 34교) – 교육청 자체 운영교 포함 추정
A20: 경북 | B20: 85 | C20: =COUNTIFS('AI 중점학교'!$B$5:$B$989,"경북") -> 84 | D20: =IFERROR(C20/B20,0) -> 0.98823529 | E20: 공개 | F20: - | G20: =COUNTIFS('AI·디지털 선도학교'!$B$5:$B$1058,"경북") -> 150 | H20: 공개 | I20: =C20+G20 -> 234 | J20: AI: 교육부 85교 중 84교 확인
A21: 경남 | B21: 49 | C21: =COUNTIFS('AI 중점학교'!$B$5:$B$989,"경남") -> 49 | D21: =IFERROR(C21/B21,0) -> 1 | E21: 공개 | F21: - | G21: =COUNTIFS('AI·디지털 선도학교'!$B$5:$B$1058,"경남") -> 0 | H21: 미공개 | I21: =C21+G21 -> 49 | J21: 디지털 명단 비공개
A22: 제주 | B22: 11 | C22: =COUNTIFS('AI 중점학교'!$B$5:$B$989,"제주") -> 11 | D22: =IFERROR(C22/B22,0) -> 1 | E22: 공개 | F22: 50 | G22: =COUNTIFS('AI·디지털 선도학교'!$B$5:$B$1058,"제주") -> 0 | H22: 미공개 | I22: =C22+G22 -> 11 | J22: 디지털 50교 선정, 명단 비공개
A23: 전국 | B23: =SUM(B6:B22) -> 1141 | C23: =SUM(C6:C22) -> 985 | D23: =IFERROR(C23/B23,0) -> 0.86327783 | E23: 14/17 공개 | F23: - | G23: =SUM(G6:G22) -> 1054 | H23: 11/17 공개 | I23: =SUM(I6:I22) -> 2039
A25: ② AI 중점학교 — 시도 × 학교급 (확보 명단 기준)
A26: 시도 | B26: 초 | C26: 중 | D26: 고 | E26: 특수/기타 | F26: 계 | G26: 타 사업 겸임
A27: 서울 | B27: =COUNTIFS('AI 중점학교'!$B$5:$B$989,"서울",'AI 중점학교'!$E$5:$E$989,"초") -> 78 | C27: =COUNTIFS('AI 중점학교'!$B$5:$B$989,"서울",'AI 중점학교'!$E$5:$E$989,"중") -> 46 | D27: =COUNTIFS('AI 중점학교'!$B$5:$B$989,"서울",'AI 중점학교'!$E$5:$E$989,"고") -> 55 | E27: =COUNTIFS('AI 중점학교'!$B$5:$B$989,"서울",'AI 중점학교'!$E$5:$E$989,"특수/기타") -> 3 | F27: =SUM(B27:E27) -> 182 | G27: =COUNTIFS('AI 중점학교'!$B$5:$B$989,"서울",'AI 중점학교'!$I$5:$I$989,"O") -> 0
A28: 부산 | B28: =COUNTIFS('AI 중점학교'!$B$5:$B$989,"부산",'AI 중점학교'!$E$5:$E$989,"초") -> 19 | C28: =COUNTIFS('AI 중점학교'!$B$5:$B$989,"부산",'AI 중점학교'!$E$5:$E$989,"중") -> 4 | D28: =COUNTIFS('AI 중점학교'!$B$5:$B$989,"부산",'AI 중점학교'!$E$5:$E$989,"고") -> 17 | E28: =COUNTIFS('AI 중점학교'!$B$5:$B$989,"부산",'AI 중점학교'!$E$5:$E$989,"특수/기타") -> 4 | F28: =SUM(B28:E28) -> 44 | G28: =COUNTIFS('AI 중점학교'!$B$5:$B$989,"부산",'AI 중점학교'!$I$5:$I$989,"O") -> 25
A29: 대구 | B29: =COUNTIFS('AI 중점학교'!$B$5:$B$989,"대구",'AI 중점학교'!$E$5:$E$989,"초") -> 21 | C29: =COUNTIFS('AI 중점학교'!$B$5:$B$989,"대구",'AI 중점학교'!$E$5:$E$989,"중") -> 32 | D29: =COUNTIFS('AI 중점학교'!$B$5:$B$989,"대구",'AI 중점학교'!$E$5:$E$989,"고") -> 7 | E29: =COUNTIFS('AI 중점학교'!$B$5:$B$989,"대구",'AI 중점학교'!$E$5:$E$989,"특수/기타") -> 0 | F29: =SUM(B29:E29) -> 60 | G29: =COUNTIFS('AI 중점학교'!$B$5:$B$989,"대구",'AI 중점학교'!$I$5:$I$989,"O") -> 18
A30: 인천 | B30: =COUNTIFS('AI 중점학교'!$B$5:$B$989,"인천",'AI 중점학교'!$E$5:$E$989,"초") -> 36 | C30: =COUNTIFS('AI 중점학교'!$B$5:$B$989,"인천",'AI 중점학교'!$E$5:$E$989,"중") -> 37 | D30: =COUNTIFS('AI 중점학교'!$B$5:$B$989,"인천",'AI 중점학교'!$E$5:$E$989,"고") -> 33 | E30: =COUNTIFS('AI 중점학교'!$B$5:$B$989,"인천",'AI 중점학교'!$E$5:$E$989,"특수/기타") -> 1 | F30: =SUM(B30:E30) -> 107 | G30: =COUNTIFS('AI 중점학교'!$B$5:$B$989,"인천",'AI 중점학교'!$I$5:$I$989,"O") -> 2
A31: 광주 | B31: =COUNTIFS('AI 중점학교'!$B$5:$B$989,"광주",'AI 중점학교'!$E$5:$E$989,"초") -> 13 | C31: =COUNTIFS('AI 중점학교'!$B$5:$B$989,"광주",'AI 중점학교'!$E$5:$E$989,"중") -> 7 | D31: =COUNTIFS('AI 중점학교'!$B$5:$B$989,"광주",'AI 중점학교'!$E$5:$E$989,"고") -> 7 | E31: =COUNTIFS('AI 중점학교'!$B$5:$B$989,"광주",'AI 중점학교'!$E$5:$E$989,"특수/기타") -> 0 | F31: =SUM(B31:E31) -> 27 | G31: =COUNTIFS('AI 중점학교'!$B$5:$B$989,"광주",'AI 중점학교'!$I$5:$I$989,"O") -> 3
A32: 대전 | B32: =COUNTIFS('AI 중점학교'!$B$5:$B$989,"대전",'AI 중점학교'!$E$5:$E$989,"초") -> 6 | C32: =COUNTIFS('AI 중점학교'!$B$5:$B$989,"대전",'AI 중점학교'!$E$5:$E$989,"중") -> 7 | D32: =COUNTIFS('AI 중점학교'!$B$5:$B$989,"대전",'AI 중점학교'!$E$5:$E$989,"고") -> 9 | E32: =COUNTIFS('AI 중점학교'!$B$5:$B$989,"대전",'AI 중점학교'!$E$5:$E$989,"특수/기타") -> 0 | F32: =SUM(B32:E32) -> 22 | G32: =COUNTIFS('AI 중점학교'!$B$5:$B$989,"대전",'AI 중점학교'!$I$5:$I$989,"O") -> 7
A33: 울산 | B33: =COUNTIFS('AI 중점학교'!$B$5:$B$989,"울산",'AI 중점학교'!$E$5:$E$989,"초") -> 7 | C33: =COUNTIFS('AI 중점학교'!$B$5:$B$989,"울산",'AI 중점학교'!$E$5:$E$989,"중") -> 4 | D33: =COUNTIFS('AI 중점학교'!$B$5:$B$989,"울산",'AI 중점학교'!$E$5:$E$989,"고") -> 5 | E33: =COUNTIFS('AI 중점학교'!$B$5:$B$989,"울산",'AI 중점학교'!$E$5:$E$989,"특수/기타") -> 0 | F33: =SUM(B33:E33) -> 16 | G33: =COUNTIFS('AI 중점학교'!$B$5:$B$989,"울산",'AI 중점학교'!$I$5:$I$989,"O") -> 0
A34: 경기 | B34: =COUNTIFS('AI 중점학교'!$B$5:$B$989,"경기",'AI 중점학교'!$E$5:$E$989,"초") -> 98 | C34: =COUNTIFS('AI 중점학교'!$B$5:$B$989,"경기",'AI 중점학교'!$E$5:$E$989,"중") -> 46 | D34: =COUNTIFS('AI 중점학교'!$B$5:$B$989,"경기",'AI 중점학교'!$E$5:$E$989,"고") -> 55 | E34: =COUNTIFS('AI 중점학교'!$B$5:$B$989,"경기",'AI 중점학교'!$E$5:$E$989,"특수/기타") -> 1 | F34: =SUM(B34:E34) -> 200 | G34: =COUNTIFS('AI 중점학교'!$B$5:$B$989,"경기",'AI 중점학교'!$I$5:$I$989,"O") -> 0
A35: 충북 | B35: =COUNTIFS('AI 중점학교'!$B$5:$B$989,"충북",'AI 중점학교'!$E$5:$E$989,"초") -> 22 | C35: =COUNTIFS('AI 중점학교'!$B$5:$B$989,"충북",'AI 중점학교'!$E$5:$E$989,"중") -> 5 | D35: =COUNTIFS('AI 중점학교'!$B$5:$B$989,"충북",'AI 중점학교'!$E$5:$E$989,"고") -> 11 | E35: =COUNTIFS('AI 중점학교'!$B$5:$B$989,"충북",'AI 중점학교'!$E$5:$E$989,"특수/기타") -> 2 | F35: =SUM(B35:E35) -> 40 | G35: =COUNTIFS('AI 중점학교'!$B$5:$B$989,"충북",'AI 중점학교'!$I$5:$I$989,"O") -> 25
A36: 전북 | B36: =COUNTIFS('AI 중점학교'!$B$5:$B$989,"전북",'AI 중점학교'!$E$5:$E$989,"초") -> 51 | C36: =COUNTIFS('AI 중점학교'!$B$5:$B$989,"전북",'AI 중점학교'!$E$5:$E$989,"중") -> 15 | D36: =COUNTIFS('AI 중점학교'!$B$5:$B$989,"전북",'AI 중점학교'!$E$5:$E$989,"고") -> 13 | E36: =COUNTIFS('AI 중점학교'!$B$5:$B$989,"전북",'AI 중점학교'!$E$5:$E$989,"특수/기타") -> 2 | F36: =SUM(B36:E36) -> 81 | G36: =COUNTIFS('AI 중점학교'!$B$5:$B$989,"전북",'AI 중점학교'!$I$5:$I$989,"O") -> 23
A37: 전남 | B37: =COUNTIFS('AI 중점학교'!$B$5:$B$989,"전남",'AI 중점학교'!$E$5:$E$989,"초") -> 28 | C37: =COUNTIFS('AI 중점학교'!$B$5:$B$989,"전남",'AI 중점학교'!$E$5:$E$989,"중") -> 18 | D37: =COUNTIFS('AI 중점학교'!$B$5:$B$989,"전남",'AI 중점학교'!$E$5:$E$989,"고") -> 16 | E37: =COUNTIFS('AI 중점학교'!$B$5:$B$989,"전남",'AI 중점학교'!$E$5:$E$989,"특수/기타") -> 0 | F37: =SUM(B37:E37) -> 62 | G37: =COUNTIFS('AI 중점학교'!$B$5:$B$989,"전남",'AI 중점학교'!$I$5:$I$989,"O") -> 19
A38: 경북 | B38: =COUNTIFS('AI 중점학교'!$B$5:$B$989,"경북",'AI 중점학교'!$E$5:$E$989,"초") -> 44 | C38: =COUNTIFS('AI 중점학교'!$B$5:$B$989,"경북",'AI 중점학교'!$E$5:$E$989,"중") -> 15 | D38: =COUNTIFS('AI 중점학교'!$B$5:$B$989,"경북",'AI 중점학교'!$E$5:$E$989,"고") -> 23 | E38: =COUNTIFS('AI 중점학교'!$B$5:$B$989,"경북",'AI 중점학교'!$E$5:$E$989,"특수/기타") -> 2 | F38: =SUM(B38:E38) -> 84 | G38: =COUNTIFS('AI 중점학교'!$B$5:$B$989,"경북",'AI 중점학교'!$I$5:$I$989,"O") -> 23
A39: 경남 | B39: =COUNTIFS('AI 중점학교'!$B$5:$B$989,"경남",'AI 중점학교'!$E$5:$E$989,"초") -> 29 | C39: =COUNTIFS('AI 중점학교'!$B$5:$B$989,"경남",'AI 중점학교'!$E$5:$E$989,"중") -> 4 | D39: =COUNTIFS('AI 중점학교'!$B$5:$B$989,"경남",'AI 중점학교'!$E$5:$E$989,"고") -> 16 | E39: =COUNTIFS('AI 중점학교'!$B$5:$B$989,"경남",'AI 중점학교'!$E$5:$E$989,"특수/기타") -> 0 | F39: =SUM(B39:E39) -> 49 | G39: =COUNTIFS('AI 중점학교'!$B$5:$B$989,"경남",'AI 중점학교'!$I$5:$I$989,"O") -> 0
A40: 제주 | B40: =COUNTIFS('AI 중점학교'!$B$5:$B$989,"제주",'AI 중점학교'!$E$5:$E$989,"초") -> 3 | C40: =COUNTIFS('AI 중점학교'!$B$5:$B$989,"제주",'AI 중점학교'!$E$5:$E$989,"중") -> 0 | D40: =COUNTIFS('AI 중점학교'!$B$5:$B$989,"제주",'AI 중점학교'!$E$5:$E$989,"고") -> 8 | E40: =COUNTIFS('AI 중점학교'!$B$5:$B$989,"제주",'AI 중점학교'!$E$5:$E$989,"특수/기타") -> 0 | F40: =SUM(B40:E40) -> 11 | G40: =COUNTIFS('AI 중점학교'!$B$5:$B$989,"제주",'AI 중점학교'!$I$5:$I$989,"O") -> 0
A41: 계 | B41: =SUM(B27:B40) -> 455 | C41: =SUM(C27:C40) -> 240 | D41: =SUM(D27:D40) -> 275 | E41: =SUM(E27:E40) -> 15 | F41: =SUM(F27:F40) -> 985 | G41: =SUM(G27:G40) -> 145
A43: ③ AI·디지털 선도학교 — 시도 × 학교급 (확보 명단 기준)
...

Sheet AI 중점학교
A1: 2026 AI 중점학교 명단 — 전국(공개 시도)
A2: 출처: 각 시도교육청 누리집 공개 선정 명단(2026) / 연락처·주소: 나이스 교육정보 개방포털 학교기본정보 / 주황색 머리글(노란 칸)은 영업 관리용 입력 칸. 학생·교원수는 추후 학교알리미 기준 입력.
A4: No | B4: 시도 | C4: 관할 교육지원청 | D4: 시군구 | E4: 학교급 | F4: 설립 | G4: 학교명 | H4: 운영 유형 | I4: 디지털 선도학교 겸임 | J4: 대표전화 | K4: 홈페이지 | L4: 주소 | M4: 학생수 | N4: 교원수 | O4: 영업 담당자 | P4: 최근 연락일 | Q4: 진행상태 | R4: 030 단체 가입 | S4: 메모
A5: 1 | B5: 서울 | C5: 강남서초교육지원청 | D5: 강남구 | E5: 초 | F5: 공립 | G5: 서울개원초등학교 | H5: 문화확산형 | J5: 02-2138-1940 | K5: http://gaewon.sen.es.kr | L5: 서울특별시 강남구 선릉로 29
A6: 2 | B6: 서울 | C6: 강남서초교육지원청 | D6: 강남구 | E6: 초 | F6: 공립 | G6: 서울개일초등학교 | H6: 문화확산형 | J6: 02-571-8320 | K6: http://gaeil.sen.es.kr | L6: 서울특별시 강남구 개포로 401
A7: 3 | B7: 서울 | C7: 강남서초교육지원청 | D7: 강남구 | E7: 초 | F7: 공립 | G7: 서울구룡초등학교 | H7: 문화확산형 | J7: 02-573-5017 | K7: http://kuryong.sen.es.kr | L7: 서울특별시 강남구 개포로 263
A8: 4 | B8: 서울 | C8: 강남서초교육지원청 | D8: 강남구 | E8: 초 | F8: 공립 | G8: 서울삼릉초등학교 | H8: 문화확산형 | J8: 02-545-4502 | K8: http://srng.sen.es.kr | L8: 서울특별시 강남구 봉은사로63길 22
A9: 5 | B9: 서울 | C9: 강남서초교육지원청 | D9: 강남구 | E9: 중 | F9: 공립 | G9: 개포중학교 | H9: 중심형 | J9: 02-2138-1631 | K9: http://gaepo.sen.ms.kr | L9: 서울특별시 강남구 선릉로 9
A10: 6 | B10: 서울 | C10: 강남서초교육지원청 | D10: 강남구 | E10: 중 | F10: 공립 | G10: 청담중학교 | H10: 문화확산형 | J10: 02-511-5151 | K10: http://cheongdam.sen.ms.kr | L10: 서울특별시 강남구 압구정로61길 36
A11: 7 | B11: 서울 | C11: 강남서초교육지원청 | D11: 강남구 | E11: 중 | F11: 사립 | G11: 휘문중학교 | H11: 문화확산형 | J11: 02-500-9700 | K11: http://whimoon.sen.ms.kr | L11: 서울특별시 강남구 역삼로 541
A12: 8 | B12: 서울 | C12: 강남서초교육지원청 | D12: 서초구 | E12: 초 | F12: 공립 | G12: 서울방일초등학교 | H12: 중심형 | J12: 02-3472-5142 | K12: http://bangil.sen.es.kr | L12: 서울특별시 서초구 방배로18길 52
A13: 9 | B13: 서울 | C13: 강남서초교육지원청 | D13: 서초구 | E13: 초 | F13: 공립 | G13: 서울서이초등학교 | H13: 문화확산형 | J13: 02-3474-7021 | K13: http://seoi.sen.es.kr | L13: 서울특별시 서초구 서운로 35
A14: 10 | B14: 서울 | C14: 강남서초교육지원청 | D14: 서초구 | E14: 초 | F14: 공립 | G14: 서울양재초등학교 | H14: 문화확산형 | J14: 02-573-4432 | K14: http://yangjae.sen.es.kr | L14: 서울특별시 서초구 바우뫼로18길 14
A15: 11 | B15: 서울 | C15: 강남서초교육지원청 | D15: 서초구 | E15: 초 | F15: 공립 | G15: 서울원촌초등학교 | H15: 중심형 | J15: 02-536-0816 | K15: http://wonchon.sen.es.kr | L15: 서울특별시 서초구 사평대로45길 26
A16: 12 | B16: 서울 | C16: 강남서초교육지원청 | D16: 서초구 | E16: 중 | F16: 공립 | G16: 내곡중학교 | H16: 중심형 | J16: 02-571-9532 | K16: http://naegok.sen.ms.kr | L16: 서울특별시 서초구 청계산로7길 9-20
... A187: 183 | B187: 부산 | C187: 교육청 직속 | D187: 강서구 | E187: 특수/기타 | F187: 공립 | G187: 부산한솔학교 | H187: 문화확산형 | J187: 051-260-2800 | K187: http://hansol.sc.kr | L187: 부산광역시 강서구 명지오션시티2로 86
A188: 184 | B188: 부산 | C188: 교육청 직속 | D188: 금정구 | E188: 고 | F188: 사립 | G188: 대진전자통신고등학교 | H188: 선도형 | I188: O | J188: 051-582-8100 | K188: http://www.pdj.hs.kr | L188: 부산광역시 금정구 수림로 92
A189: 185 | B189: 부산 | C189: 교육청 직속 | D189: 금정구 | E189: 특수/기타 | F189: 사립 | G189: 부산은애학교 | H189: 문화확산형 | I189: O | J189: 051-508-0606 | K189: http://school.busanedu.net | L189: 부산광역시 금정구 청룡예전로 107
A190: 186 | B190: 부산 | C190: 교육청 직속 | D190: 기장군 | E190: 특수/기타 | F190: 사립 | G190: 부산성우학교 | H190: 문화확산형 | I190: O | J190: 051-911-1000 | K190: http://sungwoo.sc.kr | L190: 부산광역시 기장군 장안읍 대룡2길 45
A191: 187 | B191: 부산 | C191: 교육청 직속 | D191: 기장군 | E191: 특수/기타 | F191: 공립 | G191: 부산해마루학교 | H191: 문화확산형 | I191: O | J191: 051-720-0000 | K191: http://haemaru.sc.kr | L191: 부산광역시 기장군 정관읍 모전로 23
A192: 188 | B192: 부산 | C192: 교육청 직속 | D192: 남구 | E192: 고 | F192: 사립 | G192: 대양고등학교 | H192: 문화확산형 | J192: 051-640-0580 | K192: http://www.daeyang.hs.kr | L192: 부산광역시 남구 지게골로 128-27
A193: 189 | B193: 부산 | C193: 교육청 직속 | D193: 남구 | E193: 고 | F193: 사립 | G193: 배정고등학교 | H193: 문화확산형 | J193: 051-632-4743 | K193: http://baejeong.hs.kr | L193: 부산광역시 남구 장고개로85번길 14-16
A194: 190 | B194: 부산 | C194: 교육청 직속 | D194: 남구 | E194: 고 | F194: 사립 | G194: 한얼고등학교 | H194: 중심형 | J194: 051-637-5101 | K194: http://haneol.hs.kr | L194: 부산광역시 남구 고동골로69번가길 54
A195: 191 | B195: 부산 | C195: 교육청 직속 | D195: 동구 | E195: 고 | F195: 사립 | G195: 부산컴퓨터과학고등학교 | H195: 선도형 | I195: O | J195: 051-460-0500 | K195: http://www.pcs.hs.kr | L195: 부산광역시 동구 초량로80번길 5
A196: 192 | B196: 부산 | C196: 교육청 직속 | D196: 부산진구 | E196: 고 | F196: 공립 | G196: 개금고등학교 | H196: 중심형 | J196: 051-890-5600 | K196: http://kaekeum.hs.kr | L196: 부산광역시 부산진구 백양대로208번길 71
A197: 193 | B197: 부산 | C197: 교육청 직속 | D197: 부산진구 | E197: 고 | F197: 사립 | G197: 부산동성고등학교 | H197: 선도형 | I197: O | J197: 051-802-4631 | K197: http://school.busanedu.net/psdongsung-h | L197: 부산광역시 부산진구 동성로 16
A198: 194 | B198: 부산 | C198: 교육청 직속 | D198: 부산진구 | E198: 고 | F198: 사립 | G198: 부산마케팅고등학교 | H198: 문화확산형 | I198: O | J198: 051-803-1264 | K198: http://www.marketing.hs.kr | L198: 부산광역시 부산진구 봉수로 13
A199: 195 | B199: 부산 | C199: 교육청 직속 | D199: 북구 | E199: 고 | F199: 공립 | G199: 금곡고등학교 | H199: 중심형 | J199: 051-330-2100 | K199: http://www.geumgok.hs.kr | L199: 부산광역시 북구 화명신도시로 236
A200: 196 | B200: 부산 | C200: 교육청 직속 | D200: 북구 | E200: 고 | F200: 사립 | G200: 삼정고등학교 | H200: 중심형 | J200: 051-361-9802 | K200: http://www.sj.hs.kr | L200: 부산광역시 북구 시랑로118번길 53
A201: 197 | B201: 부산 | C201: 교육청 직속 | D201: 북구 | E201: 고 | F201: 사립 | G201: 성도고등학교 | H201: 중심형 | J201: 051-332-0601 | K201: http://www.sungdo.hs.kr | L201: 부산광역시 북구 시랑로132번길 87
A202: 198 | B202: 부산 | C202: 교육청 직속 | D202: 사하구 | E202: 고 | F202: 사립 | G202: 대동고등학교 | H202: 문화확산형 | I202: O | J202: 051-292-1697 | K202: http://www.ddhs.hs.kr | L202: 부산광역시 사하구 을숙도대로709번길 27
A203: 199 | B203: 부산 | C203: 교육청 직속 | D203: 사하구 | E203: 고 | F203: 사립 | G203: 동아고등학교 | H203: 문화확산형 | I203: O | J203: 051-290-5000 | K203: http://dong-a.hs.kr | L203: 부산광역시 사하구 괴정로244번길 63
A204: 200 | B204: 부산 | C204: 교육청 직속 | D204: 사하구 | E204: 고 | F204: 공립 | G204: 부산일과학고등학교 | H204: 선도형 | J204: 051-290-6800 | K204: http://bsis.hs.kr | L204: 부산광역시 사하구 제석로 242
A205: 201 | B205: 부산 | C205: 교육청 직속 | D205: 사하구 | E205: 고 | F205: 사립 | G205: 부일전자디자인고등학교 | H205: 문화확산형 | J205: 051-208-7401 | K205: http://www.buil.hs.kr | L205: 부산광역시 사하구 감천로73번길 36
A206: 202 | B206: 부산 | C206: 교육청 직속 | D206: 연제구 | E206: 고 | F206: 사립 | G206: 이사벨고등학교 | H206: 선도형 | I206: O | J206: 051-590-2150 | K206: http://www.isabelle.hs.kr | L206: 부산광역시 연제구 중앙대로 1197
A207: 203 | B207: 부산 | C207: 교육청 직속 | D207: 영도구 | E207: 고 | F207: 사립 | G207: 부산보건고등학교 | H207: 중심형 | I207: O | J207: 051-418-9254 | K207: http://busanhc.com | L207: 부산광역시 영도구 절영로 163
A208: 204 | B208: 부산 | C208: 남부교육지원청 | D208: 부산진구 | E208: 중 | F208: 사립 | G208: 항도중학교 | H208: 중심형 | I208: O | J208: 051-809-1910 | K208: http://www.hangdo.ms.kr | L208: 부산광역시 부산진구 동성로118번길 44
A209: 205 | B209: 부산 | C209: 동래교육지원청 | D209: 금정구 | E209: 중 | F209: 공립 | G209: 금양중학교 | H209: 문화확산형 | J209: 051-580-0600 | K209: http://geumyang.ms.kr | L209: 부산광역시 금정구 기찰로22번길 37
A210: 206 | B210: 부산 | C210: 동래교육지원청 | D210: 동래구 | E210: 초 | F210: 공립 | G210: 명서초등학교 | H210: 문화확산형 | I210: O | J210: 051-524-7837 | K210: http://www.myongseo.es.kr | L210: 부산광역시 동래구 명서로 121
A211: 207 | B211: 부산 | C211: 동래교육지원청 | D211: 동래구 | E211: 중 | F211: 공립 | G211: 사직중학교 | H211: 문화확산형 | J211: 051-501-2561 | K211: http://sajik.ms.kr | L211: 부산광역시 동래구 쇠미로51번길 30
...

Sheet AI·디지털 선도학교
A1: 2026 AI·디지털 활용 선도학교 명단 — 전국(공개 시도)
A2: 출처: 각 시도교육청 누리집 공개 선정 명단(2026) / 연락처·주소: 나이스 교육정보 개방포털 학교기본정보 / 주황색 머리글(노란 칸)은 영업 관리용 입력 칸. 학생·교원수는 추후 학교알리미 기준 입력.
A4: No | B4: 시도 | C4: 관할 교육지원청 | D4: 시군구 | E4: 학교급 | F4: 설립 | G4: 학교명 | H4: 운영 유형 | I4: AI 중점학교 겸임 | J4: 대표전화 | K4: 홈페이지 | L4: 주소 | M4: 학생수 | N4: 교원수 | O4: 영업 담당자 | P4: 최근 연락일 | Q4: 진행상태 | R4: 030 단체 가입 | S4: 메모
A5: 1 | B5: 서울 | E5: 고 | G5: 화곡보건경영고등학교 | H5: 선도학교 | S5: 나이스 미매칭 – 교명 확인 필요
A6: 2 | B6: 서울 | C6: 강남서초교육지원청 | D6: 강남구 | E6: 초 | F6: 공립 | G6: 서울개현초등학교 | H6: 선도학교 | J6: 02-2138-1937 | K6: http://gaehyeon.sen.es.kr | L6: 서울특별시 강남구 선릉로 15
A7: 3 | B7: 서울 | C7: 강남서초교육지원청 | D7: 강남구 | E7: 초 | F7: 공립 | G7: 서울대곡초등학교 | H7: 선도학교 | J7: 02-565-1942 | K7: http://seouldaegok.sen.es.kr | L7: 서울특별시 강남구 남부순환로 3022
A8: 4 | B8: 서울 | C8: 강남서초교육지원청 | D8: 강남구 | E8: 초 | F8: 공립 | G8: 서울도성초등학교 | H8: 선도학교 | J8: 02-567-0039 | K8: http://seouldoseong.sen.es.kr | L8: 서울특별시 강남구 역삼로 313
A9: 5 | B9: 서울 | C9: 강남서초교육지원청 | D9: 강남구 | E9: 초 | F9: 공립 | G9: 서울언북초등학교 | H9: 선도학교 | J9: 02-514-5981 | K9: http://eonbuk.sen.es.kr | L9: 서울특별시 강남구 삼성로135길 42
A10: 6 | B10: 서울 | C10: 강남서초교육지원청 | D10: 강남구 | E10: 초 | F10: 공립 | G10: 서울역삼초등학교 | H10: 선도학교 | J10: 02-563-9168 | K10: http://yeoksam.sen.es.kr | L10: 서울특별시 강남구 강남대로66길 21
A11: 7 | B11: 서울 | C11: 강남서초교육지원청 | D11: 강남구 | E11: 초 | F11: 공립 | G11: 서울학동초등학교 | H11: 선도학교 | J11: 02-546-5185 | K11: http://hakdong.sen.es.kr | L11: 서울특별시 강남구 선릉로115길 42
A12: 8 | B12: 서울 | C12: 강남서초교육지원청 | D12: 강남구 | E12: 중 | F12: 공립 | G12: 대명중학교 | H12: 선도학교 | J12: 02-563-3701 | K12: http://daemyeong.sen.ms.kr | L12: 서울특별시 강남구 역삼로87길 26
A13: 9 | B13: 서울 | C13: 강남서초교육지원청 | D13: 강남구 | E13: 중 | F13: 공립 | G13: 대청중학교 | H13: 선도학교 | J13: 02-553-9830 | K13: http://daecheong.sen.ms.kr | L13: 서울특별시 강남구 양재천로 321
A14: 10 | B14: 서울 | C14: 강남서초교육지원청 | D14: 강남구 | E14: 중 | F14: 공립 | G14: 세곡중학교 | H14: 선도학교 | J14: 02-2040-2900 | K14: http://segok.sen.ms.kr | L14: 서울특별시 강남구 자곡로 81
A15: 11 | B15: 서울 | C15: 강남서초교육지원청 | D15: 서초구 | E15: 초 | F15: 공립 | G15: 서울반원초등학교 | H15: 선도학교 | J15: 02-599-5662 | K15: http://banwon.sen.es.kr | L15: 서울특별시 서초구 잠원로3길 28
A16: 12 | B16: 서울 | C16: 강남서초교육지원청 | D16: 서초구 | E16: 초 | F16: 공립 | G16: 서울원명초등학교 | H16: 선도학교 | J16: 02-593-4492 | K16: http://wonmyong.sen.es.kr | L16: 서울특별시 서초구 고무래로 90-6
A17: 13 | B17: 서울 | C17: 강남서초교육지원청 | D17: 서초구 | E17: 중 | F17: 공립 | G17: 경원중학교 | H17: 선도학교 | J17: 02-593-6578 | K17: http://gyeongwon.sen.ms.kr | L17: 서울특별시 서초구 신반포로33길 39
... A194: 190 | B194: 서울 | C194: 중부교육지원청 | D194: 중구 | E194: 중 | F194: 공립 | G194: 금호중학교 | H194: 선도학교 | J194: 02-2088-0549 | K194: http://geumho.sen.ms.kr | L194: 서울특별시 중구 청구로 6
A195: 191 | B195: 부산 | C195: 교육청 직속 | D195: 금정구 | E195: 고 | F195: 사립 | G195: 대진전자통신고등학교 | H195: 선도학교 | I195: O | J195: 051-582-8100 | K195: http://www.pdj.hs.kr | L195: 부산광역시 금정구 수림로 92
A196: 192 | B196: 부산 | C196: 교육청 직속 | D196: 금정구 | E196: 고 | F196: 사립 | G196: 부산정보관광고등학교 | H196: 선도학교 | J196: 051-518-7922 | K196: http://www.pusan-ith.hs.kr | L196: 부산광역시 금정구 동현로 37
A197: 193 | B197: 부산 | C197: 교육청 직속 | D197: 금정구 | E197: 특수/기타 | F197: 사립 | G197: 부산은애학교 | H197: 선도학교 | I197: O | J197: 051-508-0606 | K197: http://school.busanedu.net | L197: 부산광역시 금정구 청룡예전로 107
A198: 194 | B198: 부산 | C198: 교육청 직속 | D198: 기장군 | E198: 특수/기타 | F198: 사립 | G198: 부산성우학교 | H198: 선도학교 | I198: O | J198: 051-911-1000 | K198: http://sungwoo.sc.kr | L198: 부산광역시 기장군 장안읍 대룡2길 45
A199: 195 | B199: 부산 | C199: 교육청 직속 | D199: 기장군 | E199: 특수/기타 | F199: 공립 | G199: 부산해마루학교 | H199: 선도학교 | I199: O | J199: 051-720-0000 | K199: http://haemaru.sc.kr | L199: 부산광역시 기장군 정관읍 모전로 23
A200: 196 | B200: 부산 | C200: 교육청 직속 | D200: 남구 | E200: 고 | F200: 사립 | G200: 동명공업고등학교 | H200: 선도학교 | J200: 051-610-2527 | K200: http://tm.hs.kr | L200: 부산광역시 남구 신선로 410
A201: 197 | B201: 부산 | C201: 교육청 직속 | D201: 남구 | E201: 고 | F201: 사립 | G201: 배정미래고등학교 | H201: 선도학교 | J201: 051-635-2291 | K201: http://mr.hs.kr | L201: 부산광역시 남구 장고개로85번길 14-40
A202: 198 | B202: 부산 | C202: 교육청 직속 | D202: 남구 | E202: 고 | F202: 사립 | G202: 세연고등학교 | H202: 선도학교 | J202: 051-632-4251 | K202: http://seyeon.hs.kr | L202: 부산광역시 남구 진남로 82-19
A203: 199 | B203: 부산 | C203: 교육청 직속 | D203: 동구 | E203: 고 | F203: 사립 | G203: 부산컴퓨터과학고등학교 | H203: 선도학교 | I203: O | J203: 051-460-0500 | K203: http://www.pcs.hs.kr | L203: 부산광역시 동구 초량로80번길 5
A204: 200 | B204: 부산 | C204: 교육청 직속 | D204: 동래구 | E204: 고 | F204: 사립 | G204: 용인고등학교 | H204: 선도학교 | J204: 051-525-0029 | K204: http://psyongin.hs.kr | L204: 부산광역시 동래구 시실로107번길 37
A205: 201 | B205: 부산 | C205: 교육청 직속 | D205: 부산진구 | E205: 고 | F205: 사립 | G205: 부산동성고등학교 | H205: 선도학교 | I205: O | J205: 051-802-4631 | K205: http://school.busanedu.net/psdongsung-h | L205: 부산광역시 부산진구 동성로 16
A206: 202 | B206: 부산 | C206: 교육청 직속 | D206: 부산진구 | E206: 고 | F206: 사립 | G206: 부산마케팅고등학교 | H206: 선도학교 | I206: O | J206: 051-803-1264 | K206: http://www.marketing.hs.kr | L206: 부산광역시 부산진구 봉수로 13
A207: 203 | B207: 부산 | C207: 교육청 직속 | D207: 부산진구 | E207: 고 | F207: 사립 | G207: 세정고등학교 | H207: 선도학교 | J207: 051-860-1500 | K207: http://www.sejeong.hs.kr | L207: 부산광역시 부산진구 양정로 88-12
A208: 204 | B208: 부산 | C208: 교육청 직속 | D208: 사상구 | E208: 고 | F208: 사립 | G208: 대덕여자고등학교 | H208: 선도학교 | J208: 051-309-8810 | K208: http://daeduk.hs.kr | L208: 부산광역시 사상구 백양대로804번길 42-55
A209: 205 | B209: 부산 | C209: 교육청 직속 | D209: 사하구 | E209: 고 | F209: 사립 | G209: 대광고등학교 | H209: 선도학교 | J209: 051-292-3225 | K209: http://www.daegwang.hs.kr | L209: 부산광역시 사하구 동매로 135
A210: 206 | B210: 부산 | C210: 교육청 직속 | D210: 사하구 | E210: 고 | F210: 사립 | G210: 대동고등학교 | H210: 선도학교 | I210: O | J210: 051-292-1697 | K210: http://www.ddhs.hs.kr | L210: 부산광역시 사하구 을숙도대로709번길 27
A211: 207 | B211: 부산 | C211: 교육청 직속 | D211: 사하구 | E211: 고 | F211: 사립 | G211: 동아고등학교 | H211: 선도학교 | I211: O | J211: 051-290-5000 | K211: http://dong-a.hs.kr | L211: 부산광역시 사하구 괴정로244번길 63
A212: 208 | B212: 부산 | C212: 교육청 직속 | D212: 서구 | E212: 고 | F212: 사립 | G212: 경성전자고등학교 | H212: 선도학교 | J212: 051-253-2450 | K212: http://www.kse.hs.kr | L212: 부산광역시 서구 꽃마을로 25
A213: 209 | B213: 부산 | C213: 교육청 직속 | D213: 수영구 | E213: 고 | F213: 사립 | G213: 덕문여자고등학교 | H213: 선도학교 | J213: 051-756-1802 | K213: http://www.dukmoon.hs.kr | L213: 부산광역시 수영구 연수로310번길 114
A214: 210 | B214: 부산 | C214: 교육청 직속 | D214: 연제구 | E214: 고 | F214: 사립 | G214: 계성여자고등학교 | H214: 선도학교 | J214: 051-503-4894 | K214: http://school.busanedu.net/gyeseong-gc-h | L214: 부산광역시 연제구 해맞이로109번길 47
A215: 211 | B215: 부산 | C215: 교육청 직속 | D215: 연제구 | E215: 고 | F215: 사립 | G215: 이사벨고등학교 | H215: 선도학교 | I215: O | J215: 051-590-2150 | K215: http://www.isabelle.hs.kr | L215: 부산광역시 연제구 중앙대로 1197
A216: 212 | B216: 부산 | C216: 교육청 직속 | D216: 영도구 | E216: 고 | F216: 사립 | G216: 부산보건고등학교 | H216: 선도학교 | I216: O | J216: 051-418-9254 | K216: http://busanhc.com | L216: 부산광역시 영도구 절영로 163
A217: 213 | B217: 부산 | C217: 교육청 직속 | D217: 영도구 | E217: 고 | F217: 공립 | G217: 부산영상예술고등학교 | H217: 선도학교 | J217: 051-419-0322 | K217: http://visual.hs.kr | L217: 부산광역시 영도구 영상길 100
...
